Workbook

Sheet DATOS
B1: 2021 | C1: 2022 | D1: 2023 | E1: 2024 | F1: 2025 | G1: Promedios
A2: Prima emitida | B2: 6.2441218e+10 | C2: 6.9680097e+10 | D2: 7.9147328e+10 | E2: 8.4281016e+10 | F2: 9.0255207e+10
A3: Incremento/Decremento (%) | B3: N/A | C3: =(C2/B2)-1 -> 0.11593109 | D3: =(D2/C2)-1 -> 0.13586708 | E3: =(E2/D2)-1 -> 0.064862427 | F3: =(F2/E2)-1 -> 0.070884183 | G3: =AVERAGE(C3:F3) -> 0.096886196
A4: Costo Neto de Adquisición | B4: 8.7233918e+09 | C4: 9.7815608e+09 | D4: 1.3643041e+10 | E4: 1.2754955e+10 | F4: 1.3517235e+10
A5: % de costo de admin/prima | B5: =B4/B2 -> 0.13970566 | C5: =C4/C2 -> 0.14037812 | D5: =D4/D2 -> 0.17237526 | E5: =E4/E2 -> 0.15133841 | F5: =F4/F2 -> 0.14976682 | G5: =AVERAGE(B5:F5) -> 0.15071285
A6: Costo Neto de Siniestralidad | B6: 4.9202383e+10 | C6: 4.5669918e+10 | D6: 5.0692296e+10 | E6: 5.8294249e+10 | F6: 6.5734909e+10
A7: Incremento/Decremento (%) | B7: N/A | C7: =(C6/B6)-1 -> -0.071794577 | D7: =(D6/C6)-1 -> 0.10997124 | E7: =(E6/D6)-1 -> 0.14996268 | F7: =(F6/E6)-1 -> 0.1276397 | G7: =AVERAGE(C7:F7) -> 0.078944761
A8: Gastos de operación Netos | B8: 4.3025259e+09 | C8: 4.4522894e+09 | D8: 4.9386839e+09 | E8: 5.2942491e+09 | F8: 5.2540609e+09
A9: % de costos de operación/prima | B9: =B8/B2 -> 0.06890522 | C9: =C8/C2 -> 0.063896143 | D9: =D8/D2 -> 0.062398618 | E9: =E8/E2 -> 0.062816626 | F9: =F8/F2 -> 0.058213383 | G9: =AVERAGE(B9:F9) -> 0.063245998
A11: Utilidad/perdida del ejercicio | B11: 3078499571 | C11: 9786050231 | D11: 8.1784179e+09 | E11: 9.8298564e+09 | F11: 9.9788719e+09
C14: Suposicion, se mantienen las primas del ciclo anterior.
B15: Estimado 2026 | C15: 46048 | D15: 46079 | E15: 46107 | F15: 46138 | G15: 46168 | H15: 46199 | I15: 46229 | J15: 46260 | K15: 46291 | L15: 46321 | M15: 46352 | N15: 46382
A16: Proyeccion de la prima emitida | B16: =F2*(1+G3) -> 9.8999691e+10 | C16: =$F$2*(1+($G$3/12)) -> 9.0983914e+10 | D16: =($B$16-$C$16)/11 -> 7.2870697e+08 | E16: =($B$16-$C$16)/11 -> 7.2870697e+08 | F16: =($B$16-$C$16)/11 -> 7.2870697e+08 | G16: =($B$16-$C$16)/11 -> 7.2870697e+08 | H16: =($B$16-$C$16)/11 -> 7.2870697e+08 | I16: =($B$16-$C$16)/11 -> 7.2870697e+08 | J16: =($B$16-$C$16)/11 -> 7.2870697e+08 | K16: =($B$16-$C$16)/11 -> 7.2870697e+08 | ... N16: =($B$16-$C$16)/11 -> 7.2870697e+08
A17: Proyeccion del costo neto de siniestralidad | B17: =F6*(1+G7) -> 7.0924336e+10 | C17: =$B$17/12 -> 5.9103613e+09 | D17: =$B$17/12 -> 5.9103613e+09 | E17: =$B$17/12 -> 5.9103613e+09 | F17: =$B$17/12 -> 5.9103613e+09 | G17: =$B$17/12 -> 5.9103613e+09 | H17: =$B$17/12 -> 5.9103613e+09 | I17: =$B$17/12 -> 5.9103613e+09 | J17: =$B$17/12 -> 5.9103613e+09 | ... N17: =$B$17/12 -> 5.9103613e+09
C22: 9.9788719e+09
C23: 9.0255207e+10 | D23: =C22/C23 -> 0.11056284

Sheet PROYECCION
A1: DATOS | B1: 2021 | C1: 2022 | D1: 2023 | E1: 2024 | F1: 2025 | G1: Promedios | J1: Observaciones de la tabla
A2: Prima emitida | B2: 6.2441218e+10 | C2: 6.9680097e+10 | D2: 7.9147328e+10 | E2: 8.4281016e+10 | F2: 9.0255207e+10 | H2: =Table1[[#This Row],[2025]]*(1+G3) -> 9.8999691e+10 | I2: 1 | J2: Esta tabla contiene la informacion escencial de los estados financieros de MetLife del 2021 al 2025, inclusive. | S2: 1. Primas emitidas
A3: Incremento/Decremento (%) | B3: N/A | C3: =(C2/B2)-1 -> 0.11593109 | D3: =(D2/C2)-1 -> 0.13586708 | E3: =(E2/D2)-1 -> 0.064862427 | F3: =(F2/E2)-1 -> 0.070884183 | G3: =AVERAGE(C3:F3) -> 0.096886196 | I3: 2 | J3: Usando la informacion registrada, se calculan cuatro estadisticos importantes: (1) El promedio del incremento de la prima emitida; (2) el promedio del costo neto de adquisicion; (3) El promedio del costo neto de adquisicion; y (4) el promedio de costo neto de siniestralidad. | T3: Falta tomar en cuenta primas cedidas, de retencion e incremento neto de la reserva de riesgos en curso y fianzas en vigor
A4: Costo Neto de Adquisición | B4: 8.7233918e+09 | C4: 9.7815608e+09 | D4: 1.3643041e+10 | E4: 1.2754955e+10 | F4: 1.3517235e+10 | T4: Probablemente el mejor dato a tomar en cuenta sean las primas de retencion devengadas
A5: % de costo de admin/prima | B5: =B4/B2 -> 0.13970566 | C5: =C4/C2 -> 0.14037812 | D5: =D4/D2 -> 0.17237526 | E5: =E4/E2 -> 0.15133841 | F5: =F4/F2 -> 0.14976682 | G5: =AVERAGE(B5:F5) -> 0.15071285 | S5: 2. (-) Costo de adquisicion
A6: Costo Neto de Siniestralidad | B6: 4.9202383e+10 | C6: 4.5669918e+10 | D6: 5.0692296e+10 | E6: 5.8294249e+10 | F6: 6.5734909e+10 | I6: 3 | J6: Para plantear escenarios y hacer recomendaciones de objetivos para mejorar el rendimiento de la aseguradora, nos centraremos en analizar y realizar proyecciones para distintos valores de estos estadisticos. | T6: No hay problema con este
A7: Incremento/Decremento (%) | B7: N/A | C7: =(C6/B6)-1 -> -0.071794577 | D7: =(D6/C6)-1 -> 0.10997124 | E7: =(E6/D6)-1 -> 0.14996268 | F7: =(F6/E6)-1 -> 0.1276397 | G7: =AVERAGE(C7:F7) -> 0.078944761 | S7: 3. (-) Costo de siniestralidad
A8: Gastos de operación Netos | B8: 4.3025259e+09 | C8: 4.4522894e+09 | D8: 4.9386839e+09 | E8: 5.2942491e+09 | F8: 5.2540609e+09 | T8: No hay problema con este
A9: % de costos de operación/prima | B9: =B8/B2 -> 0.06890522 | C9: =C8/C2 -> 0.063896143 | D9: =D8/D2 -> 0.062398618 | E9: =E8/E2 -> 0.062816626 | F9: =F8/F2 -> 0.058213383 | G9: =AVERAGE(B9:F9) -> 0.063245998 | S9: 3. (-) Gastos de operacion
A10: Utilidad/perdida del ejercicio | B10: 3078499571 | C10: 9786050231 | D10: 8.1784179e+09 | E10: 9.8298564e+09 | F10: 9.9788719e+09 | T10: No hay problema con este
A11: Rentabilidad del ejercicio | B11: =B10/B2 -> 0.049302363 | C11: =C10/C2 -> 0.14044255 | D11: =D10/D2 -> 0.10333157 | E11: =E10/E2 -> 0.11663192 | F11: =F10/F2 -> 0.11056284
A12: Resultado Integral de Financiamiento | B12: 8496951934 | C12: 10957656219 | D12: 1.1517904e+10 | E12: 1.2889709e+10 | F12: 1.2583277e+10 | S12: EXTRA
A13: Incremento/Decremento (%) | B13: N/A | C13: =(C12/B12)-1 -> 0.28959847 | D13: =(D12/C12)-1 -> 0.05112846 | E13: =(E12/D12)-1 -> 0.11910191 | F13: =(F12/E12)-1 -> -0.023773357 | G13: =AVERAGE(Table1[[#This Row],[2022]:[2025]]) -> 0.10901387 | S13: 1 | T13: Una parte importante son los resultados integrales de financiamiento, esto no lo estamos tomando en cuenta.
A14: Primas cedidas | F14: 35890000
B15: =B2-B4-B6-B8+B12 -> 8.7098697e+09 | F15: =F14/F2 -> 0.00039765019 | H15: =H2*F15 -> 39367246
A16: Utilidad/Perdida de la Operacion | B16: =B2-B4-B6-B8 -> 2.1291774e+08 | C16: =C2-C4-C6-C8 -> 9.7763282e+09 | D16: =D2-D4-D6-D8 -> 9.8733072e+09 | E16: =E2-E4-E6-E8 -> 7.9375635e+09 | F16: =F2-F4-F6-F8 -> 5.7490018e+09 | H16: Primas retenidas | I16: =H2-H15 -> 9.8960323e+10
A17: ISR de la operacion
S18: 2
C19: Suposicion, se mantienen las primas del ciclo anterior.
B20: Estimado 2026 | C20: 46023 | D20: 46054 | E20: 46082 | F20: 46113 | G20: 46143 | H20: 46174 | I20: 46204 | J20: 46235 | K20: 46266 | L20: 46296 | M20: 46327 | N20: 46357
A21: Proyeccion de la prima emitida | B21: =F2*(1+G3) -> 9.8999691e+10 | C21: =$F$2*(1+($G$3/12)) -> 9.0983914e+10 | D21: =($B$21-$C$21)/11 -> 7.2870697e+08 | E21: =($B$21-$C$21)/11 -> 7.2870697e+08 | F21: =($B$21-$C$21)/11 -> 7.2870697e+08 | G21: =($B$21-$C$21)/11 -> 7.2870697e+08 | H21: =($B$21-$C$21)/11 -> 7.2870697e+08 | I21: =($B$21-$C$21)/11 -> 7.2870697e+08 | J21: =($B$21-$C$21)/11 -> 7.2870697e+08 | K21: =($B$21-$C$21)/11 -> 7.2870697e+08 | ... N21: =($B$21-$C$21)/11 -> 7.2870697e+08
A22: Proyeccion del costo neto de siniestralidad | B22: =F6*(1+G7) -> 7.0924336e+10 | C22: =$B$22/12 -> 5.9103613e+09 | D22: =$B$22/12 -> 5.9103613e+09 | E22: =$B$22/12 -> 5.9103613e+09 | F22: =$B$22/12 -> 5.9103613e+09 | G22: =$B$22/12 -> 5.9103613e+09 | H22: =$B$22/12 -> 5.9103613e+09 | I22: =$B$22/12 -> 5.9103613e+09 | J22: =$B$22/12 -> 5.9103613e+09 | ... N22: =$B$22/12 -> 5.9103613e+09
A23: Proyeccion del RIF | B23: =F12*(1+G13) -> 1.3955029e+10
A25: Prima de Riesgo | B25: 0.27 | C25: qr
A26: G. Admon | B26: =ROUND(DATOS!$G$9, 6) -> 0.063246 | C26: Gastos de administracion | G26: 2025 | I26: 2026
A27: Bonos | B27: 0.02 | C27: Gastos de Adquisicion | F27: 12000000000 | G27: 12500000000 | I27: =G27*(1+H28) -> 13125000000
A28: Comisiones | B28: =ROUND((DATOS!$G$5-$B$27)/2, 6) -> 0.065356 | H28: 0.05
A29: O.G.Adq. | B29: =ROUND((DATOS!$G$5-$B$27)/2, 6) -> 0.065356 | P29: Suposiciones
A30: I.V.A. | B30: 0.16 | O30: 1 | P30: Todos los asegurados mantienen su seguro para el año 2026.
A31: inflacion | B31: 0.04
A32: Derechos de Poliza | B32: 0.02 | O32: 2 | P32: Todas los seguros son pagados anualmente, al inicio de cada ciclo.
A33: Impuestos sobre la utilidad | B33: 0.35
O34: 3 | P34: El cierre del ciclo contable sucede el 31 de Diciembre.
A35: Rendimiento de inversion: | B35: =(1+F35)/(1+B31)-1 -> 0.030673077 | C35: real anual | E35: CETES 364 dias | F35: 0.0719 | G35: anual nominal
O36: 3.1 | P36: Una implicacion de que el ciclo contable cierre el 31 de Diciembre, es que las primas que se reciban en Enero del 2027 no se contaran para el calculo de la utilidad/perdida neta del ejercicio. Lo que si, es que se tendra que contabilizar los intereses por inversiones de este ultimo periodo (por eso se agrego una columna extra donde solo hay el dato del rendimiento de la reserva).
A37: Analisis
A39: PROYECCION | B39: Mensual | D39: % reserva invertida | E39: 0.5 | M39: Fin del ciclo contable
A41: Periodo | B41: 46023 | C41: 46054 | D41: 46082 | E41: 46113 | F41: 46143 | G41: 46174 | H41: 46204 | I41: 46235 | J41: 46266 | K41: 46296 | L41: 46327 | M41: 46357 | N41: 46388
A43: Ingresos
A44: Primas | B44: 9.0983914e+10 | C44: 7.2870697e+08 | D44: 7.2870697e+08 | E44: 7.2870697e+08 | F44: 7.2870697e+08 | G44: 7.2870697e+08 | H44: 7.2870697e+08 | I44: 7.2870697e+08 | J44: 7.2870697e+08 | K44: 7.2870697e+08 | L44: 7.2870697e+08 | M44: 7.2870697e+08
...

Sheet Sheet1
B2: Punto a mejorar | C2: Como mejorarlo
A3: 1 | B3: No solo tomar en cuenta las primas emitidas, sino tambien las primas cedidas. | C3: Calcular el promedio de la tasa de retencion (primas retenidas/emitidas)
A4: 2 | B4: Tambien tomar en cuenta los incrementos/decrementos netos de la reserva de riesgos en curso y de fianzas en vigor
A5: 3 | B5: Proyectar tambien el RIF | C5: Proyectar el total de inversiones para el 2026. Calcular el promedio de la razon (inversiones/RIF). Multiplicar el total de inversiones proyectado por el promedio de la razon y pum, proyectamos el RIF.
A6: 4 | B6: Ajustar el ingreso mensual, no todas se pagan al inicio del ano
B10: Principal ingreso de una aseguradora es el RIF
B14: Ingresos | D14: Comentarios
B15: Proyeccion de primas emitidas | C15: Promedio de tasas de incremento. | D15: Es una mejor idea amortizar el total de la prima a lo largo de los 12 meses de 2026, que asumir que todos las polizas del ano anterior se pagan en enero + la proporcion del incremento amortizado mensual en los 12 meses.
B16: Proyeccion de primas cedidas | C16: Promedio de proporcion con respecto a primas cedidas.
B17: Proyeccion de incrementos/decrementos netos de la reserva de riesgos en curso y de fianzas en vigor
B19: Costos
B20: Costo neto de adquisicion | C20: Promedio de proporcion con respecto a primas cedidas
B21: Costo neto de siniestralidad | C21: Promedio de tasas de incremento. | D21: Deberia agregar una proyeccion para los siniestros cedidos?
B22: Costo neto de operacion | C22: Promedio de proporcion con respecto a primas cedidas
B24: Inversiones
B25: RIF

Sheet PROYECCION_MEJORADA
A1: DATOS | B1: 2021 | C1: 2022 | D1: 2023 | E1: 2024 | F1: 2025 | G1: Promedios | J1: Observaciones de la tabla
A2: Prima emitida | B2: 6.2441218e+10 | C2: 6.9680097e+10 | D2: 7.9147328e+10 | E2: 8.4281016e+10 | F2: 9.0255207e+10 | H2: =Table13[[#This Row],[2025]]*(1+G3) -> 9.8999691e+10 | I2: 1 | J2: Esta tabla contiene la informacion escencial de los estados financieros de MetLife del 2021 al 2025, inclusive. | S2: 1. Primas emitidas
A3: Incremento/Decremento (%) | B3: N/A | C3: =(C2/B2)-1 -> 0.11593109 | D3: =(D2/C2)-1 -> 0.13586708 | E3: =(E2/D2)-1 -> 0.064862427 | F3: =(F2/E2)-1 -> 0.070884183 | G3: =AVERAGE(C3:F3) -> 0.096886196 | I3: 2 | J3: Usando la informacion registrada, se calculan cuatro estadisticos importantes: (1) El promedio del incremento de la prima emitida; (2) el promedio del costo neto de adquisicion; (3) El promedio del costo neto de adquisicion; y (4) el promedio de costo neto de siniestralidad. | T3: Falta tomar en cuenta primas cedidas, de retencion e incremento neto de la reserva de riesgos en curso y fianzas en vigor
A4: Costo Neto de Adquisición | B4: 8.7233918e+09 | C4: 9.7815608e+09 | D4: 1.3643041e+10 | E4: 1.2754955e+10 | F4: 1.3517235e+10 | T4: Probablemente el mejor dato a tomar en cuenta sean las primas de retencion devengadas
A5: % de costo de admin/prima | B5: =B4/B2 -> 0.13970566 | C5: =C4/C2 -> 0.14037812 | D5: =D4/D2 -> 0.17237526 | E5: =E4/E2 -> 0.15133841 | F5: =F4/F2 -> 0.14976682 | G5: =AVERAGE(B5:F5) -> 0.15071285 | S5: 2. (-) Costo de adquisicion
A6: Costo Neto de Siniestralidad | B6: 4.9202383e+10 | C6: 4.5669918e+10 | D6: 5.0692296e+10 | E6: 5.8294249e+10 | F6: 6.5734909e+10 | I6: 3 | J6: Para plantear escenarios y hacer recomendaciones de objetivos para mejorar el rendimiento de la aseguradora, nos centraremos en analizar y realizar proyecciones para distintos valores de estos estadisticos. | T6: No hay problema con este
A7: Incremento/Decremento (%) | B7: N/A | C7: =(C6/B6)-1 -> -0.071794577 | D7: =(D6/C6)-1 -> 0.10997124 | E7: =(E6/D6)-1 -> 0.14996268 | F7: =(F6/E6)-1 -> 0.1276397 | G7: =AVERAGE(C7:F7) -> 0.078944761 | S7: 3. (-) Costo de siniestralidad
A8: Gastos de operación Netos | B8: 4.3025259e+09 | C8: 4.4522894e+09 | D8: 4.9386839e+09 | E8: 5.2942491e+09 | F8: 5.2540609e+09 | T8: No hay problema con este
A9: % de costos de operación/prima | B9: =B8/B2 -> 0.06890522 | C9: =C8/C2 -> 0.063896143 | D9: =D8/D2 -> 0.062398618 | E9: =E8/E2 -> 0.062816626 | F9: =F8/F2 -> 0.058213383 | G9: =AVERAGE(B9:F9) -> 0.063245998 | S9: 3. (-) Gastos de operacion
A10: Utilidad/perdida del ejercicio | B10: 3078499571 | C10: 9786050231 | D10: 8.1784179e+09 | E10: 9.8298564e+09 | F10: 9.9788719e+09 | T10: No hay problema con este
A11: Rentabilidad del ejercicio | B11: =B10/B2 -> 0.049302363 | C11: =C10/C2 -> 0.14044255 | D11: =D10/D2 -> 0.10333157 | E11: =E10/E2 -> 0.11663192 | F11: =F10/F2 -> 0.11056284
A12: Resultado Integral de Financiamiento | B12: 8496951934 | C12: 10957656219 | D12: 1.1517904e+10 | E12: 1.2889709e+10 | F12: 1.2583277e+10 | S12: Extra
A13: Incremento/Decremento (%) | B13: N/A | C13: =(C12/B12)-1 -> 0.28959847 | D13: =(D12/C12)-1 -> 0.05112846 | E13: =(E12/D12)-1 -> 0.11910191 | F13: =(F12/E12)-1 -> -0.023773357 | G13: =AVERAGE(Table13[[#This Row],[2022]:[2025]]) -> 0.10901387 | S13: 1 | T13: Una parte importante son los resultados integrales de financiamiento, esto no lo estamos tomando en cuenta.
A16: Inversiones | E16: 1.2968258e+11 | F16: 1.4325722e+11
A17: Resultado Integral de Financiamiento | B17: 8496951934 | C17: 10957656219 | D17: 1.1517904e+10 | E17: 1.2889709e+10 | F17: 1.2583277e+10
F18: =F17/E16 -> 0.097031361
B21: =B2-B4-B6-B8+B12 -> 8.7098697e+09 | F21: =F14/F2 -> 0 | H21: =H2*F21 -> 0
A22: Utilidad/Perdida de la Operacion | B22: =B2-B4-B6-B8 -> 2.1291774e+08 | C22: =C2-C4-C6-C8 -> 9.7763282e+09 | D22: =D2-D4-D6-D8 -> 9.8733072e+09 | E22: =E2-E4-E6-E8 -> 7.9375635e+09 | F22: =F2-F4-F6-F8 -> 5.7490018e+09 | H22: Primas retenidas | I22: =H2-H21 -> 9.8999691e+10
A23: ISR de la operacion
S24: 2
C25: Suposicion, se mantienen las primas del ciclo anterior.
B26: Estimado 2026 | C26: 46023 | D26: 46054 | E26: 46082 | F26: 46113 | G26: 46143 | H26: 46174 | I26: 46204 | J26: 46235 | K26: 46266 | L26: 46296 | M26: 46327 | N26: 46357
A27: Proyeccion de la prima emitida | B27: =F2*(1+G3) -> 9.8999691e+10 | C27: =$F$2*(1+($G$3/12)) -> 9.0983914e+10 | D27: =($B$27-$C$27)/11 -> 7.2870697e+08 | E27: =($B$27-$C$27)/11 -> 7.2870697e+08 | F27: =($B$27-$C$27)/11 -> 7.2870697e+08 | G27: =($B$27-$C$27)/11 -> 7.2870697e+08 | H27: =($B$27-$C$27)/11 -> 7.2870697e+08 | I27: =($B$27-$C$27)/11 -> 7.2870697e+08 | J27: =($B$27-$C$27)/11 -> 7.2870697e+08 | K27: =($B$27-$C$27)/11 -> 7.2870697e+08 | ... N27: =($B$27-$C$27)/11 -> 7.2870697e+08
A28: Proyeccion del costo neto de siniestralidad | B28: =F6*(1+G7) -> 7.0924336e+10 | C28: =$B$28/12 -> 5.9103613e+09 | D28: =$B$28/12 -> 5.9103613e+09 | E28: =$B$28/12 -> 5.9103613e+09 | F28: =$B$28/12 -> 5.9103613e+09 | G28: =$B$28/12 -> 5.9103613e+09 | H28: =$B$28/12 -> 5.9103613e+09 | I28: =$B$28/12 -> 5.9103613e+09 | J28: =$B$28/12 -> 5.9103613e+09 | ... N28: =$B$28/12 -> 5.9103613e+09
A29: Proyeccion del RIF | B29: =F12*(1+G13) -> 1.3955029e+10
A31: Prima de Riesgo | B31: 0.27 | C31: qr
A32: G. Admon | B32: =ROUND(DATOS!$G$9, 6) -> 0.063246 | C32: Gastos de administracion | G32: 2025 | I32: 2026
A33: Bonos | B33: 0.02 | C33: Gastos de Adquisicion | F33: 12000000000 | G33: 12500000000 | I33: =G33*(1+H34) -> 13125000000
A34: Comisiones | B34: =ROUND((DATOS!$G$5-$B$33)/2, 6) -> 0.065356 | H34: 0.05
A35: O.G.Adq. | B35: =ROUND((DATOS!$G$5-$B$33)/2, 6) -> 0.065356 | P35: Suposiciones
A36: I.V.A. | B36: 0.16 | O36: 1 | P36: Todos los asegurados mantienen su seguro para el año 2026.
A37: inflacion | B37: 0.04
A38: Derechos de Poliza | B38: 0.02 | O38: 2 | P38: Todas los seguros son pagados anualmente, al inicio de cada ciclo.
A39: Impuestos sobre la utilidad | B39: 0.35
O40: 3 | P40: El cierre del ciclo contable sucede el 31 de Diciembre.
A41: Rendimiento de inversion: | B41: =(1+F41)/(1+B37)-1 -> 0.030673077 | C41: real anual | E41: CETES 364 dias | F41: 0.0719 | G41: anual nominal
O42: 3.1 | P42: Una implicacion de que el ciclo contable cierre el 31 de Diciembre, es que las primas que se reciban en Enero del 2027 no se contaran para el calculo de la utilidad/perdida neta del ejercicio. Lo que si, es que se tendra que contabilizar los intereses por inversiones de este ultimo periodo (por eso se agrego una columna extra donde solo hay el dato del rendimiento de la reserva).
A43: Analisis
A45: PROYECCION | B45: Mensual | D45: % reserva invertida | E45: 0.5 | M45: Fin del ciclo contable
A47: Periodo | B47: 46023 | C47: 46054 | D47: 46082 | E47: 46113 | F47: 46143 | G47: 46174 | H47: 46204 | I47: 46235 | J47: 46266 | K47: 46296 | L47: 46327 | M47: 46357 | N47: 46388
...
